Workbook

Sheet README
A1: Personality Panic - Balance Lock v6
A3: Purpose | B3: Master stat/action/job/audio data workbook for the first playable MVP. Send together with Personality_Panic_MVP_Master_Manual_v2.docx.
A4: Core loop | B4: Choose personality -> move map -> enter building -> take action -> stats/costs/time change -> upkeep/rent/pet consequences -> final score.
A5: End condition | B5: When one player maxes all 4 main stats, finish the current round; highest final score wins. Podium screen shows 1st-4th.
A6: Main stats | B6: Connection, Health, Career, Happiness
A7: Upkeep stats | B7: Coolness Factor, Critical Thinking, Enlightenment, Money
A8: Pet stats | B8: Pet Happiness, Pet Health
A9: Money rule | B9: Money and cash are the same resource/stat.
A10: Scaling | B10: T = stat target. Short T=100, Medium T=500, Long T=1000. Action gains/costs scale as % of T.
A12: WHAT CHANGED IN v2
A13: 1. Balance Patch | B13: Weakness penalties unified (main -10%, upkeep -8%), closing the v1 net-budget spread from 27 points (-2 to +25) down to 15 points (+2 to +17). Career/Money-strength types remain intentionally lowest, offset by their income/job snowball. See Balance_Audit sheet.
A14: 2. Job pay now scales with T | B14: v1 locked job pay as static, but rent/items/travel costs scale with T, which starved the economy in Medium/Long games. Dollar values in Jobs_Named are the Short (T=100) baseline; Medium = x5, Long = x10.
A15: 3. Jobs consolidated | B15: Jobs_Named (detailed per-building jobs from the Master Manual) is canonical. Jobs_Tiers keeps the generic 4-tier math as a fallback/reference.
A16: 4. Audio added | B16: Audio_Music and Audio_SFX sheets define every music and sound-effect cue, including the rent-due overmap swap every 4 turns.
A18: Sheets | B18: Settings | Personalities | Balance_Audit | Actions_Master | Items_Mall | Jobs_Named | Jobs_Tiers | Pets | Audio_Music | Audio_SFX
A20: WHAT CHANGED IN v3
A21: 1. Weekend Update card system | B21: New Cards sheet: status cards, investment outcome cards, and standing-based event cards shown at the start of each turn. Draw weights and investment resolution odds are in the same sheet.
A22: 2. Hunger/stress penalties quantified | B22: Previously the docs said 'time penalty' with no number. Now locked: Hunger -4 Time Units, Stress -2 Time Units, penalties stack, minimum 1 Time Unit per turn.
A23: 3. Pet death rework | B23: Old Healthy->Hungry->Sick->Critical->Dead states replaced: miss 1 feeding = Sad Pet, miss 2 consecutive = Starving Pet (final warning), miss 3 consecutive = pet dies (tombstone in housing, owner Happiness -> 0). Feeding resets the counter. Re-adoption allowed.
A25: WHAT CHANGED IN v4
A26: 1. Game length scaling FIXED | B26: Stat cap (T) and gain/economy base (B) are now separate. v3 scaled both by the same multiplier, so Short/Medium/Long took the same number of turns and only changed the size of the numbers. Now Medium takes ~2x and Long ~2.9x the turns of Short. See Settings.
A27: 2. Investment system rebuilt | B27: New Investments sheet defines the full asset lifecycle. Purchases no longer grant free Money (v3 double-counting bug), savings/bonds now cost a real principal and are capped at one holding each, and a Cash Out action was added.
A28: 3. Crypto/Stocks odds retuned | B28: Crypto is now extreme by standing (leader trap / trailer comeback). Stocks are mild, with a new SIDEWAYS MARKET flat outcome that dominates for 2nd/3rd place, plus a MARKET CRASH big-loss card.
A29: 4. Mall prices raised and housing-gated | B29: Electronics, appliances, and furniture cost roughly 2-3x more, and many now require Luxury housing. Recurring costs (food, rent, pet upkeep) unchanged so survival is no harder, only accumulation slower.
A30: 5. Pet shop actions reworked | B30: Bribe Inspector: money cost + Critical Thinking gain. Contact P.I.T.A.: big one-time Happiness gain, once per game.
A31: 6. Read Tiny Print defined | B31: Grants INFORMED: downgrades the next Big Loss to a Small Loss, then is consumed.
A32: 7. Card modifier rule locked | B32: Card effects ignore personality/pet/item modifiers and the income cap.
A33: 8. Weekend Cards toggle is now three-way | B33: Full / Essential / Off (debug). Investments always resolve regardless.
A34: 9. Lifestyle Loan repayment defined | B34: +15%B now, -5%B at the start of each of the next 4 turns.
A36: Sheets | B36: Settings | Personalities | Balance_Audit | Actions_Master | Items_Mall | Investments | Jobs_Named | Jobs_Tiers | Pets | Audio_Music | Audio_SFX | Cards
A38: WHAT CHANGED IN v5
A39: 1. High IQ University rebuilt | B39: New Education_Paths sheet: 5 paths x 6 courses = 30 courses, with costs, click counts, strict unlock order, one-time completion, and job-tier gating. Replaces Take Class / Finish Undergrad / Master's / PhD, and fixes the bug where courses were unavailable.
A40: 2. Promotions removed | B40: New Job_Progression sheet. Ask for Promotion is deleted and there is no loyalty requirement. Tiers unlock on accumulated work clicks PLUS the matching education path.
A41: 3. Mall repriced to absolute dollars | B41: All 33 listed items set to the specified prices ($50 casual clothes ... $2000 car), 5-25x the v4 values.
A42: 4. Money economy rebuilt to match | B42: Job pay, rent, food, and the homeless cheque all rescaled. Without this the new prices would be unreachable: a $2000 car at the old $9 low wage was 222 work clicks.
A43: 5. Mall penalties removed | B43: Durag and Crocodile Sandals no longer carry stat penalties. No mall item has a penalty.
A44: 6. Flat trigger bonuses added | B44: 16 home items now grant fixed point bonuses when their trigger action happens at home (beds on sleep, bookshelf/plants/mirror/dining table/stove/hot tub on relax, desk/ergonomic chair on work-from-home, pet bed/pet toys on play, cold plunge on exercise, fridge/vacuum one-time on purchase).
A45: 7. Home fixtures exemption | B45: The best-item-per-slot rule no longer applies to home fixtures, so multiple owned fixtures each fire. Only one bed counts.
A46: 8. Fridge gating | B46: 2-week and 4-week groceries now require a fridge; a new 2-week option was added.
A47: OPEN DECISION | B47: Job click gates are absolute, so Short games realistically cannot reach High/Max tier. See the pacing warning in Job_Progression for Option A (keep) vs Option B (scale by mode).
...

Sheet Settings
A1: Setting | B1: Value | C1: Notes
A2: Current Gain/Economy Base B | B2: 100 | C2: The number ALL percentages resolve against (gains, penalties, prices, rent, pay, card effects). Set to 100 / 250 / 350. This is NOT the stat cap.
A3: Short Game B (gain/economy base) | B3: 100 | C3: Short game economy base
A4: Medium Game B (gain/economy base) | B4: 250 | C4: Medium game economy base
A5: Long Game B (gain/economy base) | B5: 350 | C5: Long game economy base
A6: STAT CAPS T (endgame threshold — scale FASTER than B)
A7: Short Game T (stat cap) | B7: 100 | C7: Turn ratio T/B = 1.00 -> baseline length
A8: Medium Game T (stat cap) | B8: 500 | C8: Turn ratio T/B = 2.00 -> about twice as many turns as Short
A9: Long Game T (stat cap) | B9: 1000 | C9: Turn ratio T/B = 2.86 -> about 2.9x as many turns as Short
A10: Current Stat Cap T | B10: 100 | C10: Set to match the selected mode. Endgame triggers when a player hits T in all 4 main stats.
A11: Time Units per Turn | B11: 40 | C11: BUILD: 40 per turn (Game Setup offers 12-50). Sheet TU costs are used as authored. Per-turn rules written for a ~6 TU turn are much weaker at 40.
A12: Rent Interval (turns) | B12: 4 | C12: Rent-due overmap music also swaps in on these turns.
A13: Turn Timer Options (sec) | B13: 30 / 60 / 90 / 120 / Unlimited | C13: Chosen on Game Setup screen
A14: Max Players | B14: 4 | C14: 1 host + up to 3 joiners; CPU bots fill empty slots (min 2 total participants)
A16: Gain Tier | B16: % of B | C16: Meaning (resolves against B, NOT the stat cap)
A17: Tiny | B17: 0.025 | C17: Small action
A18: Standard | B18: 0.05 | C18: Normal action
A19: Strong | B19: 0.08 | C19: Good action
A20: Premium | B20: 0.12 | C20: Expensive/limited action
A21: Milestone | B21: 0.15 | C21: Degree/unlock/major action
A22: Major Milestone | B22: 0.2 | C22: Huge late-game action
A24: PERSONALITY MODIFIERS v2 (BALANCE PATCH)
A25: Stat | B25: Strength Bonus | C25: Weakness Penalty (v2) | D25: Max Final Multiplier | E25: Notes
A26: Connection | B26: 0.2 | C26: -0.1 | D26: 1.45 | E26: Main stat
A27: Health | B27: 0.2 | C27: -0.1 | D27: 1.45 | E27: Main stat
A28: Happiness | B28: 0.2 | C28: -0.1 | D28: 1.45 | E28: Main stat
A29: Career | B29: 0.1 | C29: -0.1 | D29: 1.25 | E29: Engine stat: weak strength (snowballs), full-size weakness
A30: Coolness Factor | B30: 0.15 | C30: -0.08 | D30: 1.35 | E30: Upkeep stat
A31: Critical Thinking | B31: 0.15 | C31: -0.08 | D31: 1.35 | E31: Upkeep stat
A32: Enlightenment | B32: 0.15 | C32: -0.08 | D32: 1.35 | E32: Upkeep stat
A33: Money | B33: 0.1 | C33: -0.08 | D33: 1.25 | E33: Engine stat: weak strength (snowballs), full-size weakness
A35: Final Gain Formula | B35: Base Gain x Personality Modifier x Pet Modifier x Best Item Modifier x Temporary Modifier, then clamp to the stat's Max Final Multiplier.
A36: Final Score Formula | B36: Connection + Health + Career + Happiness + AVG(Coolness, Critical Thinking, Enlightenment, Money) + AVG(Pet Happiness, Pet Health)
A38: UPKEEP TIME PENALTIES (locked in v3)
A39: Penalty | B39: Value | C39: Rule
A40: Hunger (forgot to eat last turn) | B40: -25% of the turn | C40: BUILD: 25% of next turn's Time Units (2026-07-20), not a flat -4.
A41: Stress (no relaxation for 2 turns) | B41: -15% of the turn | C41: BUILD: 15% of next turn's Time Units plus 5%B Health and 5%B Happiness.
A42: Stacking rule | B42: Both can apply | C42: Penalties stack (-6 total possible) but a turn never drops below 1 Time Unit.
A44: GAME LENGTH SCALING (fixed in v4)
A45: Problem in v3 | B45: Stat caps AND stat gains both scaled with T, so every action filled the same percentage of the bar in every mode (a 5% action needed ~20 uses in Short, Medium and Long alike). The modes only changed the size of the numbers, not the length of the game.
...

Sheet Personalities
A1: Type | B1: Main Strength | C1: Upkeep Strength | D1: Main Weakness | E1: Upkeep Weakness | F1: Notes
A2: ENFP | B2: Happiness | C2: Coolness Factor | D2: Health | E2: Money
A3: ESTP | B3: Health | C3: Money | D3: Happiness | E3: Enlightenment | F3: Engine type (Career or Money strength): lower net budget by design, offset by income/economic snowball
A4: ENTP | B4: Health | C4: Critical Thinking | D4: Connection | E4: Enlightenment
A5: ESFP | B5: Happiness | C5: Coolness Factor | D5: Career | E5: Critical Thinking
A6: ENFJ | B6: Connection | C6: Enlightenment | D6: Health | E6: Money
A7: ESFJ | B7: Connection | C7: Coolness Factor | D7: Health | E7: Critical Thinking
A8: ENTJ | B8: Career | C8: Money | D8: Happiness | E8: Coolness Factor | F8: Engine type (Career or Money strength): lower net budget by design, offset by income/economic snowball
A9: ESTJ | B9: Career | C9: Money | D9: Happiness | E9: Enlightenment | F9: Engine type (Career or Money strength): lower net budget by design, offset by income/economic snowball
A10: INTJ | B10: Career | C10: Critical Thinking | D10: Health | E10: Coolness Factor | F10: Engine type (Career or Money strength): lower net budget by design, offset by income/economic snowball
A11: ISTJ | B11: Career | C11: Money | D11: Connection | E11: Coolness Factor | F11: Engine type (Career or Money strength): lower net budget by design, offset by income/economic snowball
A12: ISFJ | B12: Connection | C12: Enlightenment | D12: Happiness | E12: Critical Thinking
A13: INFJ | B13: Connection | C13: Enlightenment | D13: Career | E13: Money
A14: INFP | B14: Happiness | C14: Enlightenment | D14: Career | E14: Money
A15: ISFP | B15: Happiness | C15: Coolness Factor | D15: Career | E15: Critical Thinking
A16: ISTP | B16: Health | C16: Critical Thinking | D16: Connection | E16: Enlightenment
A17: INTP | B17: Health | C17: Critical Thinking | D17: Connection | E17: Coolness Factor

Sheet Balance_Audit
A1: Why v2 exists: in v1, strength/weakness sizes varied so much per stat that net modifier budgets ranged from -2 (ENTJ/ESTJ/ISTJ) to +25 (INFJ/INFP), a 27-point spread. v2 unifies weakness penalties (main -10, upkeep -8), closing the spread to 15 points (+2 to +17). Career/Money-strength types remain intentionally lowest, offset by their income/job snowball rather than by stat-modifier perks.
A3: Type | B3: v1 Net Budget | C3: v2 Net Budget | D3: Change | E3: Notes
A4: ENFP | B4: 18 | C4: 17 | D4: =C4-B4
A5: ESTP | B5: 8 | C5: 12 | D5: =C5-B5 | E5: Engine type: lower budget by design, offset by income/job snowball
A6: ENTP | B6: 13 | C6: 17 | D6: =C6-B6
A7: ESFP | B7: 20 | C7: 17 | D7: =C7-B7
A8: ENFJ | B8: 18 | C8: 17 | D8: =C8-B8
A9: ESFJ | B9: 13 | C9: 17 | D9: =C9-B9
A10: ENTJ | B10: -2 | C10: 2 | D10: =C10-B10 | E10: Engine type: lower budget by design, offset by income/job snowball
A11: ESTJ | B11: -2 | C11: 2 | D11: =C11-B11 | E11: Engine type: lower budget by design, offset by income/job snowball
A12: INTJ | B12: 3 | C12: 7 | D12: =C12-B12 | E12: Engine type: lower budget by design, offset by income/job snowball
A13: ISTJ | B13: -2 | C13: 2 | D13: =C13-B13 | E13: Engine type: lower budget by design, offset by income/job snowball
A14: ISFJ | B14: 13 | C14: 17 | D14: =C14-B14
A15: INFJ | B15: 25 | C15: 17 | D15: =C15-B15
A16: INFP | B16: 25 | C16: 17 | D16: =C16-B16
A17: ISFP | B17: 20 | C17: 17 | D17: =C17-B17
A18: ISTP | B18: 13 | C18: 17 | D18: =C18-B18
A19: INTP | B19: 13 | C19: 17 | D19: =C19-B19
A21: v1 spread | B21: =MAX(B4:B19)-MIN(B4:B19) | C21: v2 spread | D21: =MAX(C4:C19)-MIN(C4:C19)
A23: Ongoing rule: log the winning personality in the debug panel every playtest. If any type's win rate leaves the 15-35 percent band (4-player expected = 25 percent) over 20+ games, adjust one weakness by 1-2 points and retest.

Sheet Building_Map
A1: BUILDING MAP AND DISTANCE PAY (new in v6). Wages are no longer identical everywhere. The Corporate Soul Exchange is the hub of the map and pays the baseline; the further a building sits from it, the higher its Money Multiplier, because getting there and back costs Time Units you could have spent working. The multiplier applies to MONEY ONLY — never to Career, never to stat gains, never to card effects. Pay per click = tier pay (Job_Progression) x building Money Multiplier, rounded to the nearest dollar. Display Name is the name shown in the build; if the build renames a building, record it here.
A3: Building (canonical) | B3: Display Name in build | C3: Ring (distance from Corporate) | D3: Travel Time Units from Corporate | E3: Money Multiplier (v6) | F3: Has jobs? | G3: Pay example — Mid tier ($110 base) | H3: Notes
A4: Corporate Soul Exchange | B4: Corporate Soul Exchange | C4: 1 | D4: 0 | E4: 1 | F4: Yes | G4: =ROUND(110*E4,0) | H4: The hub. Baseline pay. Also the job board: every job change happens here.
A5: Debtstreet Capital | B5: Debtstreet Capital | C5: 1 | D5: 1 | E5: 1 | F5: Yes | G5: =ROUND(110*E5,0) | H5: Across the plaza from Corporate. Baseline pay, but the investment desk is here.
A6: Mall | B6: Mall | C6: 1 | D6: 1 | E6: 1 | F6: Yes | G6: =ROUND(110*E6,0) | H6: Baseline pay. Compensated by being where every item is bought.
A7: Air One Supermarket | B7: Air One Supermarket | C7: 2 | D7: 1 | E7: 1.1 | F7: Yes | G7: =ROUND(110*E7,0) | H7: One ring out. Food route.
A8: High IQ University | B8: High IQ University | C8: 2 | D8: 1 | E8: 1.1 | F8: Yes | G8: =ROUND(110*E8,0) | H8: One ring out. Education route.
A9: Regret Burger | B9: Regret Burger | C9: 2 | D9: 1 | E9: 1.1 | F9: Yes | G9: =ROUND(110*E9,0) | H9: One ring out. Cheap food route.
A10: Low Cost Housing | B10: Low Cost Housing | C10: 2 | D10: 1 | E10: 1 | F10: No | G10: — | H10: Starting home. No jobs. Work From Home uses the 0.85 convenience multiplier (see below).
A11: Bro Science Gym | B11: Bro Science Gym | C11: 3 | D11: 2 | E11: 1.2 | F11: Yes | G11: =ROUND(110*E11,0) | H11: Two rings out. Health and Connection route.
A12: Bad Decisions Club | B12: Bad Decisions Club | C12: 3 | D12: 2 | E12: 1.2 | F12: Yes | G12: =ROUND(110*E12,0) | H12: Two rings out. Night-side of the map.
A13: Ethical Pet Shop | B13: Ethical Pet Shop | C13: 3 | D13: 2 | E13: 1.2 | F13: Yes | G13: =ROUND(110*E13,0) | H13: Two rings out. Pet route.
A14: Luxury Apartments | B14: Heelton Heights (CONFIRM) | C14: 3 | D14: 2 | E14: 1 | F14: No | G14: — | H14: Premium home. No jobs. Work From Home uses the 0.85 convenience multiplier (see below). The playtest build calls this building Heelton Heights — confirm the mapping before shipping.
A15: Park | B15: Park | C15: 3 | D15: 2 | E15: 1 | F15: No | G15: — | H15: Recovery / homeless fallback. No jobs.
A16: Emotional Baggage Airport | B16: Emotional Baggage Airport | C16: 4 | D16: 3 | E16: 1.35 | F16: Yes | G16: =ROUND(110*E16,0) | H16: Edge of the map. Highest wage multiplier in the game — worth the trip if you are already flying.
A17: Re-Education Temple | B17: Re-Education Temple | C17: 4 | D17: 3 | E17: 1.35 | F17: Yes | G17: =ROUND(110*E17,0) | H17: Edge of the map. Highest wage multiplier in the game.
A19: RULES
A20: Money only | B20: The Money Multiplier applies ONLY to Money earned from a Work click (and Work From Home). It never touches Career gain, stat gains, card effects, or investment returns.
A21: Work From Home | B21: Work From Home at either housing building uses a Money Multiplier of 0.85. Working in your pyjamas costs no travel, so it must pay less than going in. It still counts as a work click for tier progression and still uses your current job tier.
A22: Travel is the cost | B22: Ring 3 and Ring 4 buildings must genuinely cost 2 and 3 Time Units to reach from the hub. If travel is free, the multiplier is a straight buff and the trade-off disappears.
A23: Rounding | B23: Pay per click = ROUND(tier pay x multiplier, 0). At Short a Mid click is $110 at Corporate, $121 at Air One, $132 at the Gym, $149 at the Airport.
A24: Scaling | B24: Multipliers do not change with game length. Tier pay already scales with B (Medium x2.5, Long x3.5).
A25: Ring numbers are a starting point | B25: Ring assignments here describe the intended map layout, not measured coordinates. If the built map places a building differently, update this sheet to match the map rather than moving the building.

Sheet CPU_Difficulty
A1: CPU DIFFICULTY (new in v6). Difficulty is chosen on the Game Setup screen and can be set per bot or globally for all bots. Default is Medium. Difficulty changes ONLY how bots behave and one explicitly-labelled bot-only gain multiplier. It never changes the rules, the prices, the card deck, or anything a human player experiences.
A3: Behaviour | B3: Easy | C3: Medium | D3: Hard
A4: Action choice | B4: Picks at random from the affordable actions in the building it is standing in. | C4: Scores every affordable action and picks randomly from the top 3. | D4: Scores every affordable action and always picks the best.
A5: Planning horizon | B5: One action at a time. No saving up. | C5: Plans the current turn. Will save money across 2-3 turns for a named goal. | D5: Plans several turns ahead. Saves for education paths, job tiers, and housing deliberately.
A6: Forgets to eat | B6: 40% of turns | C6: 15% of turns | D6: Never
A7: Forgets to relax | B7: 40% of stress checks | C7: 15% of stress checks | D7: Never
A8: Pays rent | B8: Only if it happens to be in the building on the due turn (often goes homeless). | C8: Pays on the due turn if it can afford it. | D8: Pre-pays and keeps a rent reserve; never goes homeless voluntarily.
A9: Education | B9: Ignores High IQ University. | C9: Completes Path 1 and Path 2 if the game runs long enough. | D9: Treats education as a priority and pushes as far up the paths as the turn count allows.
A10: Job tiers | B10: Takes whatever job it qualifies for by accident. | C10: Works toward the next tier once it is one gate away. | D10: Works the highest-paying eligible job and targets the next tier from turn 1.
A11: Travel for wages | B11: Never travels for pay; works wherever it is. | C11: Uses a nearby building. | D11: Uses the Money Multiplier: travels to a far building when it plans 2+ work clicks.
A12: Investments | B12: Does not invest. | C12: Buys Savings and Bonds only. | D12: Standing-aware: crypto when last, bonds and savings when leading, cashes out before taking the lead.
A13: Mall shopping | B13: Buys impulsively, often unaffordable-adjacent junk. | C13: Buys job-required clothing and one or two home fixtures. | D13: Buys job-required clothing first, then the highest value-per-dollar fixtures.
A14: Pet care | B14: Frequently misses feedings; may let the pet die. | C14: Feeds on the warning card. | D14: Never misses a feeding.
A15: Bot-only gain multiplier | B15: 0.85x | C15: 1.00x | D15: 1.10x
A17: Bot-only multiplier scope | B17: The 0.85x / 1.00x / 1.10x multiplier applies to a BOT's stat and money gains from ACTIONS only. It is never applied to a human player, never to card effects, and never to investment returns. Show it in the debug panel so balance tests can be run with it switched off.
A18: Per-bot or global | B18: Game Setup offers one difficulty control for all bots plus an expandable per-bot override, so a player can face one Hard bot and two Easy bots.
A19: Skipping unchanged | B19: Skip CPU Turns works identically at every difficulty. A Hard bot must not take longer in real time.
A20: Default | B20: Medium.

Sheet Actions_Master
A1: Action_ID | B1: Building | C1: Action | D1: Category | E1: Requirement / Condition | F1: Time Units | G1: Cost (xB) — 1.0 = 100% of B | H1: Cost Short | I1: Cost Medium | J1: Cost Long | K1: Gain Stat 1 | L1: Gain (xB) 1 — 1.0 = 100% of B | M1: Gain Short | N1: Gain Medium | O1: Gain Long | P1: Gain Stat 2 | Q1: Gain (xB) 2 — 1.0 = 100% of B | R1: Gain2 Short | S1: Gain2 Medium | T1: Gain2 Long | U1: Pet Gain | V1: Pet (xB) | W1: Penalty Stat 1 | X1: Penalty (xB) 1 | Y1: Penalty Stat 2 | Z1: Penalty (xB) 2 | AA1: Unlock / Effect | AB1: Balance Notes | AC1: MVP Priority | AD1: Counts As (v6) | AE1: Requires Item (v6) | AF1: Per-Turn Limit (v6) | AG1: Flat Bonus (v6) | AH1: Money Multiplier (v6) | AI1: v6 Change
A2: A001 | B2: Low Cost Housing | C2: Sleep in Bunk Bed | D2: Rest | E2: Must be housed here | F2: 2 | G2: 0 | H2: =ROUND($G2*Settings!$B$3,0) | I2: =ROUND($G2*Settings!$B$4,0) | J2: =ROUND($G2*Settings!$B$5,0) | K2: Health | L2: 0.05 | M2: =ROUND($L2*Settings!$B$3,0) | N2: =ROUND($L2*Settings!$B$4,0) | O2: =ROUND($L2*Settings!$B$5,0) | Q2: 0 | R2: =ROUND($Q2*Settings!$B$3,0) | S2: =ROUND($Q2*Settings!$B$4,0) | T2: =ROUND($Q2*Settings!$B$5,0) | V2: 0 | Z2: 0 | AA2: Reduces stress; ends hunger penalty timer if food was eaten | AB2: Safe recovery, not a winning engine | AC2: MVP | AD2: Sleep + Relax
A3: A002 | B3: Low Cost Housing | C3: Relax in Your Room | D3: Relax | E3: Must be housed here | F3: 1 | G3: 0 | H3: =ROUND($G3*Settings!$B$3,0) | I3: =ROUND($G3*Settings!$B$4,0) | J3: =ROUND($G3*Settings!$B$5,0) | K3: Happiness | L3: 0.04 | M3: =ROUND($L3*Settings!$B$3,0) | N3: =ROUND($L3*Settings!$B$4,0) | O3: =ROUND($L3*Settings!$B$5,0) | Q3: 0 | R3: =ROUND($Q3*Settings!$B$3,0) | S3: =ROUND($Q3*Settings!$B$4,0) | T3: =ROUND($Q3*Settings!$B$5,0) | V3: 0 | Z3: 0 | AA3: Counts as relaxing for 2-turn stress rule | AB3: Cheap stress management | AC3: MVP | AD3: Relax
A4: A003 | B4: Low Cost Housing | C4: Take Communal Shower | D4: Health | E4: Must be housed here | F4: 1 | G4: 0 | H4: =ROUND($G4*Settings!$B$3,0) | I4: =ROUND($G4*Settings!$B$4,0) | J4: =ROUND($G4*Settings!$B$5,0) | K4: Health | L4: 0.025 | M4: =ROUND($L4*Settings!$B$3,0) | N4: =ROUND($L4*Settings!$B$4,0) | O4: =ROUND($L4*Settings!$B$5,0) | Q4: 0 | R4: =ROUND($Q4*Settings!$B$3,0) | S4: =ROUND($Q4*Settings!$B$4,0) | T4: =ROUND($Q4*Settings!$B$5,0) | V4: 0 | Z4: 0 | AB4: Small maintenance action | AC4: MVP
A5: A004 | B5: Low Cost Housing | C5: Exercise in Former Yard | D5: Health | E5: Must be housed here | F5: 1 | G5: 0 | H5: =ROUND($G5*Settings!$B$3,0) | I5: =ROUND($G5*Settings!$B$4,0) | J5: =ROUND($G5*Settings!$B$5,0) | K5: Health | L5: 0.025 | M5: =ROUND($L5*Settings!$B$3,0) | N5: =ROUND($L5*Settings!$B$4,0) | O5: =ROUND($L5*Settings!$B$5,0) | Q5: 0 | R5: =ROUND($Q5*Settings!$B$3,0) | S5: =ROUND($Q5*Settings!$B$4,0) | T5: =ROUND($Q5*Settings!$B$5,0) | V5: 0 | W5: Happiness | X5: 0.01 | Z5: 0 | AB5: v6: Health cut from 4%B to 2.5%B and limited to 2 per turn. Free, zero-travel exercise was out-earning the gym. | AC5: MVP | AF5: 2 per turn | AI5: Health 0.04 -> 0.025; max 2 per turn
A6: A005 | B6: Low Cost Housing | C6: Decorate Your Cell | D6: Home | E6: Furniture owned | F6: 1 | G6: 0 | H6: =ROUND($G6*Settings!$B$3,0) | I6: =ROUND($G6*Settings!$B$4,0) | J6: =ROUND($G6*Settings!$B$5,0) | K6: Happiness | L6: 0.05 | M6: =ROUND($L6*Settings!$B$3,0) | N6: =ROUND($L6*Settings!$B$4,0) | O6: =ROUND($L6*Settings!$B$5,0) | Q6: 0 | R6: =ROUND($Q6*Settings!$B$3,0) | S6: =ROUND($Q6*Settings!$B$4,0) | T6: =ROUND($Q6*Settings!$B$5,0) | V6: 0 | Z6: 0 | AA6: Uses owned furniture bonus | AB6: Requires prior Mall spending | AC6: MVP
A7: A006 | B7: Low Cost Housing | C7: Hang With Pet | D7: Pet | E7: Own a pet | F7: 1 | G7: 0 | H7: =ROUND($G7*Settings!$B$3,0) | I7: =ROUND($G7*Settings!$B$4,0) | J7: =ROUND($G7*Settings!$B$5,0) | K7: Connection | L7: 0.025 | M7: =ROUND($L7*Settings!$B$3,0) | N7: =ROUND($L7*Settings!$B$4,0) | O7: =ROUND($L7*Settings!$B$5,0) | Q7: 0 | R7: =ROUND($Q7*Settings!$B$3,0) | S7: =ROUND($Q7*Settings!$B$4,0) | T7: =ROUND($Q7*Settings!$B$5,0) | U7: Pet Happiness | V7: 0.05 | Z7: 0 | AB7: Pet route support | AC7: MVP
A8: A007 | B8: Low Cost Housing | C8: Feed Pet | D8: Pet | E8: Own pet + pet food | F8: 1 | G8: 0 | H8: =ROUND($G8*Settings!$B$3,0) | I8: =ROUND($G8*Settings!$B$4,0) | J8: =ROUND($G8*Settings!$B$5,0) | L8: 0 | M8: =ROUND($L8*Settings!$B$3,0) | N8: =ROUND($L8*Settings!$B$4,0) | O8: =ROUND($L8*Settings!$B$5,0) | Q8: 0 | R8: =ROUND($Q8*Settings!$B$3,0) | S8: =ROUND($Q8*Settings!$B$4,0) | T8: =ROUND($Q8*Settings!$B$5,0) | U8: Pet Health | V8: 0.08 | Z8: 0 | AA8: Prevents pet warning/death spiral | AB8: Pet maintenance | AC8: MVP
A9: A008 | B9: Low Cost Housing | C9: Pay Low-Cost Rent | D9: Rent | E9: Always available while housed here | F9: 0 | G9: 1 | H9: =ROUND($G9*Settings!$B$3,0) | I9: =ROUND($G9*Settings!$B$4,0) | J9: =ROUND($G9*Settings!$B$5,0) | L9: 0 | M9: =ROUND($L9*Settings!$B$3,0) | N9: =ROUND($L9*Settings!$B$4,0) | O9: =ROUND($L9*Settings!$B$5,0) | Q9: 0 | R9: =ROUND($Q9*Settings!$B$3,0) | S9: =ROUND($Q9*Settings!$B$4,0) | T9: =ROUND($Q9*Settings!$B$5,0) | V9: 0 | Z9: 0 | AA9: PAY RENT. This action is ALWAYS listed in the housing menu and is never hidden, never filtered out, and never costs Time Units. It has four display states: RENT DUE (shows the amount, highlighted), PAID (shows the turn the next payment falls due), NOT YET DUE (shows turns remaining; the player may pre-pay the next cycle), and CANNOT AFFORD (greyed, shows the exact shortfall). On success: deduct the money, play PP-Money.mp3, write a log line, and set the next due turn to the current turn + the Rent Interval. If rent is still unpaid when the rent-due turn ends, the player becomes homeless. | AB9: v6 BUG FIX. Cost is a MULTIPLE of B, not a percent: 1 = $100 low rent, 4 = $400 luxury rent at the Short baseline. Reading these as 1% and 4% of B charges $1 and $4 and breaks the economy. A menu row that does nothing when clicked is the reported playtest bug. | AC9: MVP | AI9: Pay Rent rebuilt: always visible, four states, explicit handler
A10: A009 | B10: Luxury Apartments | C10: Sleep in Fancy Bed | D10: Rest | E10: Luxury apartment + any bed owned | F10: 2 | G10: 0 | H10: =ROUND($G10*Settings!$B$3,0) | I10: =ROUND($G10*Settings!$B$4,0) | J10: =ROUND($G10*Settings!$B$5,0) | K10: Health | L10: 0.08 | M10: =ROUND($L10*Settings!$B$3,0) | N10: =ROUND($L10*Settings!$B$4,0) | O10: =ROUND($L10*Settings!$B$5,0) | Q10: 0 | R10: =ROUND($Q10*Settings!$B$3,0) | S10: =ROUND($Q10*Settings!$B$4,0) | T10: =ROUND($Q10*Settings!$B$5,0) | V10: 0 | Z10: 0 | AA10: Reduces stress strongly | AB10: Premium housing advantage | AC10: MVP | AD10: Sleep + Relax | AE10: Any bed owned (Lumpy, Nice or Premium) | AI10: Now requires a bed purchase
A11: A010 | B11: Luxury Apartments | C11: Take Luxury Bath | D11: Relax | E11: Luxury apartment + Hot Tub owned | F11: 1 | G11: 0.2 | H11: =ROUND($G11*Settings!$B$3,0) | I11: =ROUND($G11*Settings!$B$4,0) | J11: =ROUND($G11*Settings!$B$5,0) | K11: Health | L11: 0.04 | M11: =ROUND($L11*Settings!$B$3,0) | N11: =ROUND($L11*Settings!$B$4,0) | O11: =ROUND($L11*Settings!$B$5,0) | P11: Happiness | Q11: 0.04 | R11: =ROUND($Q11*Settings!$B$3,0) | S11: =ROUND($Q11*Settings!$B$4,0) | T11: =ROUND($Q11*Settings!$B$5,0) | V11: 0 | Z11: 0 | AA11: Counts as relaxing | AB11: Small paid luxury action | v6.1: restored the v5.1 price that matches the painted menu ($20). | AC11: MVP | AD11: Relax | AE11: Hot Tub | AI11: Now requires a Hot Tub purchase
A12: A011 | B12: Luxury Apartments | C12: Relax in Your Suite | D12: Relax | E12: Luxury apartment + Couch owned | F12: 1 | G12: 0 | H12: =ROUND($G12*Settings!$B$3,0) | I12: =ROUND($G12*Settings!$B$4,0) | J12: =ROUND($G12*Settings!$B$5,0) | K12: Happiness | L12: 0.08 | M12: =ROUND($L12*Settings!$B$3,0) | N12: =ROUND($L12*Settings!$B$4,0) | O12: =ROUND($L12*Settings!$B$5,0) | Q12: 0 | R12: =ROUND($Q12*Settings!$B$3,0) | S12: =ROUND($Q12*Settings!$B$4,0) | T12: =ROUND($Q12*Settings!$B$5,0) | V12: 0 | Z12: 0 | AA12: Counts as relaxing | AB12: Strong happiness route | AC12: MVP | AD12: Relax | AE12: Any couch owned | AI12: Now requires a Couch purchase
A13: A012 | B13: Luxury Apartments | C13: Exercise in Condo Gym | D13: Health | E13: Luxury apartment | F13: 1 | G13: 0 | H13: =ROUND($G13*Settings!$B$3,0) | I13: =ROUND($G13*Settings!$B$4,0) | J13: =ROUND($G13*Settings!$B$5,0) | K13: Health | L13: 0.03 | M13: =ROUND($L13*Settings!$B$3,0) | N13: =ROUND($L13*Settings!$B$4,0) | O13: =ROUND($L13*Settings!$B$5,0) | Q13: 0 | R13: =ROUND($Q13*Settings!$B$3,0) | S13: =ROUND($Q13*Settings!$B$4,0) | T13: =ROUND($Q13*Settings!$B$5,0) | V13: 0 | Z13: 0 | AB13: v6: Health cut from 6%B to 3%B and limited to 2 per turn. This was the best Health-per-Time-Unit action in the game, it was free, and it cost no travel. | AC13: MVP | AF13: 2 per turn | AI13: Health 0.06 -> 0.03; max 2 per turn
A14: A013 | B14: Luxury Apartments | C14: Order Fancy Food | D14: Food | E14: Luxury apartment | F14: 1 | G14: 0.8 | H14: =ROUND($G14*Settings!$B$3,0) | I14: =ROUND($G14*Settings!$B$4,0) | J14: =ROUND($G14*Settings!$B$5,0) | K14: Happiness | L14: 0.06 | M14: =ROUND($L14*Settings!$B$3,0) | N14: =ROUND($L14*Settings!$B$4,0) | O14: =ROUND($L14*Settings!$B$5,0) | Q14: 0 | R14: =ROUND($Q14*Settings!$B$3,0) | S14: =ROUND($Q14*Settings!$B$4,0) | T14: =ROUND($Q14*Settings!$B$5,0) | V14: 0 | Z14: 0 | AA14: COUNTS AS EATING. Clears this turn's hunger requirement exactly like a Regret Burger meal or a grocery meal, and prevents the YOU FORGOT TO EAT! card next turn. | AB14: Expensive convenience | v6.1: restored the v5.1 price that matches the painted menu ($80). | AC14: MVP | AD14: Eat | AI14: Now explicitly counts as eating (Counts As = Eat)
A15: A014 | B15: Luxury Apartments | C15: Host Friends | D15: Social | E15: Luxury apartment + Fancy Dinnerware owned | F15: 2 | G15: 0.6 | H15: =ROUND($G15*Settings!$B$3,0) | I15: =ROUND($G15*Settings!$B$4,0) | J15: =ROUND($G15*Settings!$B$5,0) | K15: Connection | L15: 0.08 | M15: =ROUND($L15*Settings!$B$3,0) | N15: =ROUND($L15*Settings!$B$4,0) | O15: =ROUND($L15*Settings!$B$5,0) | P15: Coolness Factor | Q15: 0.04 | R15: =ROUND($Q15*Settings!$B$3,0) | S15: =ROUND($Q15*Settings!$B$4,0) | T15: =ROUND($Q15*Settings!$B$5,0) | V15: 0 | Z15: 0 | AB15: Luxury social route | v6.1: restored the v5.1 price that matches the painted menu ($60). | AC15: MVP | AE15: Fancy Dinnerware | AI15: Now requires Fancy Dinnerware (new item I042)
A16: A015 | B16: Luxury Apartments | C16: Work From Home | D16: Work | E16: Luxury apartment + computer + desk + job | F16: 2 | G16: 0 | H16: =ROUND($G16*Settings!$B$3,0) | I16: =ROUND($G16*Settings!$B$4,0) | J16: =ROUND($G16*Settings!$B$5,0) | K16: From job tier | L16: 0 | M16: =ROUND($L16*Settings!$B$3,0) | N16: =ROUND($L16*Settings!$B$4,0) | O16: =ROUND($L16*Settings!$B$5,0) | P16: From job tier | Q16: 0 | R16: =ROUND($Q16*Settings!$B$3,0) | S16: =ROUND($Q16*Settings!$B$4,0) | T16: =ROUND($Q16*Settings!$B$5,0) | V16: 0 | W16: Health | X16: 0.025 | Y16: Happiness | Z16: 0.025 | AA16: Counts as a Work click for tier progression. Money and Career come from the current job tier (Jobs_Named / Job_Progression), multiplied by 0.85 because working from home costs no travel. | AB16: Good but still has burnout | AC16: MVP | AD16: Work | AH16: 0.85 | AI16: Money/Career now come from job tier; 0.85 convenience multiplier
A17: A016 | B17: Luxury Apartments | C17: Pet Spa Treatment | D17: Pet | E17: Luxury apartment + own pet | F17: 1 | G17: 0.8 | H17: =ROUND($G17*Settings!$B$3,0) | I17: =ROUND($G17*Settings!$B$4,0) | J17: =ROUND($G17*Settings!$B$5,0) | L17: 0 | M17: =ROUND($L17*Settings!$B$3,0) | N17: =ROUND($L17*Settings!$B$4,0) | O17: =ROUND($L17*Settings!$B$5,0) | Q17: 0 | R17: =ROUND($Q17*Settings!$B$3,0) | S17: =ROUND($Q17*Settings!$B$4,0) | T17: =ROUND($Q17*Settings!$B$5,0) | U17: Pet Health | V17: 0.1 | Z17: 0 | AB17: Premium pet recovery | v6.1: restored the v5.1 price that matches the painted menu ($80). | AC17: MVP
A18: A017 | B18: Luxury Apartments | C18: Pay Luxury Rent | D18: Rent | E18: Always available while housed here | F18: 0 | G18: 4 | H18: =ROUND($G18*Settings!$B$3,0) | I18: =ROUND($G18*Settings!$B$4,0) | J18: =ROUND($G18*Settings!$B$5,0) | L18: 0 | M18: =ROUND($L18*Settings!$B$3,0) | N18: =ROUND($L18*Settings!$B$4,0) | O18: =ROUND($L18*Settings!$B$5,0) | Q18: 0 | R18: =ROUND($Q18*Settings!$B$3,0) | S18: =ROUND($Q18*Settings!$B$4,0) | T18: =ROUND($Q18*Settings!$B$5,0) | V18: 0 | Z18: 0 | AA18: PAY RENT. This action is ALWAYS listed in the housing menu and is never hidden, never filtered out, and never costs Time Units. It has four display states: RENT DUE (shows the amount, highlighted), PAID (shows the turn the next payment falls due), NOT YET DUE (shows turns remaining; the player may pre-pay the next cycle), and CANNOT AFFORD (greyed, shows the exact shortfall). On success: deduct the money, play PP-Money.mp3, write a log line, and set the next due turn to the current turn + the Rent Interval. If rent is still unpaid when the rent-due turn ends, the player becomes homeless. | AB18: v6 BUG FIX. Cost is a MULTIPLE of B, not a percent: 1 = $100 low rent, 4 = $400 luxury rent at the Short baseline. Reading these as 1% and 4% of B charges $1 and $4 and breaks the economy. A menu row that does nothing when clicked is the reported playtest bug. | AC18: MVP | AI18: Pay Rent rebuilt: always visible, four states, explicit handler
A19: A018 | B19: Park | C19: Take a Walk | D19: Health | E19: None | F19: 1 | G19: 0 | H19: =ROUND($G19*Settings!$B$3,0) | I19: =ROUND($G19*Settings!$B$4,0) | J19: =ROUND($G19*Settings!$B$5,0) | K19: Health | L19: 0.025 | M19: =ROUND($L19*Settings!$B$3,0) | N19: =ROUND($L19*Settings!$B$4,0) | O19: =ROUND($L19*Settings!$B$5,0) | P19: Happiness | Q19: 0.025 | R19: =ROUND($Q19*Settings!$B$3,0) | S19: =ROUND($Q19*Settings!$B$4,0) | T19: =ROUND($Q19*Settings!$B$5,0) | V19: 0 | Z19: 0 | AB19: Small free action | AC19: MVP
A20: A019 | B20: Park | C20: Touch Grass | D20: Enlightenment | E20: None | F20: 1 | G20: 0 | H20: =ROUND($G20*Settings!$B$3,0) | I20: =ROUND($G20*Settings!$B$4,0) | J20: =ROUND($G20*Settings!$B$5,0) | K20: Enlightenment | L20: 0.05 | M20: =ROUND($L20*Settings!$B$3,0) | N20: =ROUND($L20*Settings!$B$4,0) | O20: =ROUND($L20*Settings!$B$5,0) | P20: Health | Q20: 0.025 | R20: =ROUND($Q20*Settings!$B$3,0) | S20: =ROUND($Q20*Settings!$B$4,0) | T20: =ROUND($Q20*Settings!$B$5,0) | V20: 0 | Z20: 0 | AB20: Free enlightenment route | AC20: MVP
A21: A020 | B21: Park | C21: Feed Judgmental Ducks | D21: Fun | E21: None | F21: 1 | G21: 0.01 | H21: =ROUND($G21*Settings!$B$3,0) | I21: =ROUND($G21*Settings!$B$4,0) | J21: =ROUND($G21*Settings!$B$5,0) | K21: Happiness | L21: 0.04 | M21: =ROUND($L21*Settings!$B$3,0) | N21: =ROUND($L21*Settings!$B$4,0) | O21: =ROUND($L21*Settings!$B$5,0) | Q21: 0 | R21: =ROUND($Q21*Settings!$B$3,0) | S21: =ROUND($Q21*Settings!$B$4,0) | T21: =ROUND($Q21*Settings!$B$5,0) | V21: 0 | Z21: 0 | AB21: Cheap happiness | AC21: MVP
A22: A021 | B22: Park | C22: Use Restroom of Uncertainty | D22: Health | E22: None | F22: 1 | G22: 0 | H22: =ROUND($G22*Settings!$B$3,0) | I22: =ROUND($G22*Settings!$B$4,0) | J22: =ROUND($G22*Settings!$B$5,0) | K22: Health | L22: 0.02 | M22: =ROUND($L22*Settings!$B$3,0) | N22: =ROUND($L22*Settings!$B$4,0) | O22: =ROUND($L22*Settings!$B$5,0) | Q22: 0 | R22: =ROUND($Q22*Settings!$B$3,0) | S22: =ROUND($Q22*Settings!$B$4,0) | T22: =ROUND($Q22*Settings!$B$5,0) | V22: 0 | W22: Happiness | X22: 0.01 | Z22: 0 | AB22: Comedy maintenance | AC22: MVP
A23: A022 | B23: Park | C23: Nap on Park Bench | D23: Rest | E23: None | F23: 1 | G23: 0 | H23: =ROUND($G23*Settings!$B$3,0) | I23: =ROUND($G23*Settings!$B$4,0) | J23: =ROUND($G23*Settings!$B$5,0) | K23: Health | L23: 0.03 | M23: =ROUND($L23*Settings!$B$3,0) | N23: =ROUND($L23*Settings!$B$4,0) | O23: =ROUND($L23*Settings!$B$5,0) | P23: Happiness | Q23: 0.02 | R23: =ROUND($Q23*Settings!$B$3,0) | S23: =ROUND($Q23*Settings!$B$4,0) | T23: =ROUND($Q23*Settings!$B$5,0) | V23: 0 | Z23: 0 | AA23: Counts as relaxing | AB23: Free stress recovery | AC23: MVP | AD23: Relax
A24: A023 | B24: Park | C24: Pick Up Loose Change | D24: Money | E24: None | F24: 1 | G24: 0 | H24: =ROUND($G24*Settings!$B$3,0) | I24: =ROUND($G24*Settings!$B$4,0) | J24: =ROUND($G24*Settings!$B$5,0) | K24: Money | L24: 0.025 | M24: =ROUND($L24*Settings!$B$3,0) | N24: =ROUND($L24*Settings!$B$4,0) | O24: =ROUND($L24*Settings!$B$5,0) | Q24: 0 | R24: =ROUND($Q24*Settings!$B$3,0) | S24: =ROUND($Q24*Settings!$B$4,0) | T24: =ROUND($Q24*Settings!$B$5,0) | V24: 0 | Z24: 0 | AB24: Tiny money route | AC24: MVP
A25: A024 | B25: Park | C25: Homeless Support Cheque | D25: Comeback | E25: Homeless + rent cycle only | F25: 0 | G25: 0 | H25: =ROUND($G25*Settings!$B$3,0) | I25: =ROUND($G25*Settings!$B$4,0) | J25: =ROUND($G25*Settings!$B$5,0) | K25: Money | L25: 2 | M25: =ROUND($L25*Settings!$B$3,0) | N25: =ROUND($L25*Settings!$B$4,0) | O25: =ROUND($L25*Settings!$B$5,0) | Q25: 0 | R25: =ROUND($Q25*Settings!$B$3,0) | S25: =ROUND($Q25*Settings!$B$4,0) | T25: =ROUND($Q25*Settings!$B$5,0) | V25: 0 | Z25: 0 | AA25: Enough for casual clothes + low-cost rent | AB25: v5: cheque raised to $200 so it still covers casual clothes ($50) + low rent ($100) + a few meals. | AC25: MVP
A26: A025 | B26: Park | C26: Sleep in Park if Homeless | D26: Homeless | E26: Homeless | F26: 2 | G26: 0 | H26: =ROUND($G26*Settings!$B$3,0) | I26: =ROUND($G26*Settings!$B$4,0) | J26: =ROUND($G26*Settings!$B$5,0) | K26: Health | L26: 0.015 | M26: =ROUND($L26*Settings!$B$3,0) | N26: =ROUND($L26*Settings!$B$4,0) | O26: =ROUND($L26*Settings!$B$5,0) | Q26: 0 | R26: =ROUND($Q26*Settings!$B$3,0) | S26: =ROUND($Q26*Settings!$B$4,0) | T26: =ROUND($Q26*Settings!$B$5,0) | V26: 0 | W26: Happiness | X26: 0.08 | Y26: Health | Z26: 0.03 | AA26: Survive turn | AB26: Painful but recoverable | AC26: MVP | AD26: Sleep + Relax
A27: A026 | B27: Air One Supermarket | C27: Buy 1 Week of Groceries | D27: Food | E27: None | F27: 1 | G27: 0.4 | H27: =ROUND($G27*Settings!$B$3,0) | I27: =ROUND($G27*Settings!$B$4,0) | J27: =ROUND($G27*Settings!$B$5,0) | K27: Health | L27: 0.04 | M27: =ROUND($L27*Settings!$B$3,0) | N27: =ROUND($L27*Settings!$B$4,0) | O27: =ROUND($L27*Settings!$B$5,0) | Q27: 0 | R27: =ROUND($Q27*Settings!$B$3,0) | S27: =ROUND($Q27*Settings!$B$4,0) | T27: =ROUND($Q27*Settings!$B$5,0) | V27: 0 | Z27: 0 | AA27: Adds 1 week food supply | AB27: v5: 1 week groceries $40 | AC27: MVP | AD27: Food supply (not a meal)
A28: A027 | B28: Air One Supermarket | C28: Buy 1 Week of Organic Groceries | D28: Food | E28: None | F28: 1 | G28: 0.7 | H28: =ROUND($G28*Settings!$B$3,0) | I28: =ROUND($G28*Settings!$B$4,0) | J28: =ROUND($G28*Settings!$B$5,0) | K28: Health | L28: 0.08 | M28: =ROUND($L28*Settings!$B$3,0) | N28: =ROUND($L28*Settings!$B$4,0) | O28: =ROUND($L28*Settings!$B$5,0) | Q28: 0 | R28: =ROUND($Q28*Settings!$B$3,0) | S28: =ROUND($Q28*Settings!$B$4,0) | T28: =ROUND($Q28*Settings!$B$5,0) | V28: 0 | Z28: 0 | AA28: Adds premium food supply | AB28: v5: organic 1 week $70 | AC28: MVP | AD28: Food supply (not a meal)
A29: A028 | B29: Air One Supermarket | C29: Buy 4 Weeks of Groceries | D29: Food | E29: Fridge required | F29: 1 | G29: 1.3 | H29: =ROUND($G29*Settings!$B$3,0) | I29: =ROUND($G29*Settings!$B$4,0) | J29: =ROUND($G29*Settings!$B$5,0) | K29: Health | L29: 0.1 | M29: =ROUND($L29*Settings!$B$3,0) | N29: =ROUND($L29*Settings!$B$4,0) | O29: =ROUND($L29*Settings!$B$5,0) | Q29: 0 | R29: =ROUND($Q29*Settings!$B$3,0) | S29: =ROUND($Q29*Settings!$B$4,0) | T29: =ROUND($Q29*Settings!$B$5,0) | V29: 0 | Z29: 0 | AA29: Adds 4 weeks food supply | AB29: v5: 4 weeks $130; fridge required | AC29: MVP | AD29: Food supply (not a meal)
A30: A029 | B30: Air One Supermarket | C30: Buy $22 Smoothie | D30: Food | E30: None | F30: 1 | G30: 0.25 | H30: =ROUND($G30*Settings!$B$3,0) | I30: =ROUND($G30*Settings!$B$4,0) | J30: =ROUND($G30*Settings!$B$5,0) | K30: Health | L30: 0.05 | M30: =ROUND($L30*Settings!$B$3,0) | N30: =ROUND($L30*Settings!$B$4,0) | O30: =ROUND($L30*Settings!$B$5,0) | P30: Happiness | Q30: 0.02 | R30: =ROUND($Q30*Settings!$B$3,0) | S30: =ROUND($Q30*Settings!$B$4,0) | T30: =ROUND($Q30*Settings!$B$5,0) | V30: 0 | Z30: 0 | AA30: Fills hunger lightly | AB30: Expensive joke item | AC30: MVP | AD30: Eat
A31: A030 | B31: Air One Supermarket | C31: Judge Window Shoppers | D31: Personality | E31: None | F31: 1 | G31: 0 | H31: =ROUND($G31*Settings!$B$3,0) | I31: =ROUND($G31*Settings!$B$4,0) | J31: =ROUND($G31*Settings!$B$5,0) | K31: Enlightenment | L31: 0.03 | M31: =ROUND($L31*Settings!$B$3,0) | N31: =ROUND($L31*Settings!$B$4,0) | O31: =ROUND($L31*Settings!$B$5,0) | P31: Coolness Factor | Q31: 0.02 | R31: =ROUND($Q31*Settings!$B$3,0) | S31: =ROUND($Q31*Settings!$B$4,0) | T31: =ROUND($Q31*Settings!$B$5,0) | V31: 0 | Z31: 0 | AB31: Small hybrid | AC31: MVP
A32: A031 | B32: Air One Supermarket | C32: Buy Meal Prep Ingredients | D32: Food | E32: Fridge + stove | F32: 1 | G32: 0.6 | H32: =ROUND($G32*Settings!$B$3,0) | I32: =ROUND($G32*Settings!$B$4,0) | J32: =ROUND($G32*Settings!$B$5,0) | K32: Health | L32: 0.1 | M32: =ROUND($L32*Settings!$B$3,0) | N32: =ROUND($L32*Settings!$B$4,0) | O32: =ROUND($L32*Settings!$B$5,0) | Q32: 0 | R32: =ROUND($Q32*Settings!$B$3,0) | S32: =ROUND($Q32*Settings!$B$4,0) | T32: =ROUND($Q32*Settings!$B$5,0) | V32: 0 | Z32: 0 | AA32: Better food efficiency at home | AB32: Mid/late food route | AC32: MVP | AD32: Food supply (not a meal)
A33: A032 | B33: Air One Supermarket | C33: Extreme Clean Eating | D33: Food | E33: None | F33: 1 | G33: 0.8 | H33: =ROUND($G33*Settings!$B$3,0) | I33: =ROUND($G33*Settings!$B$4,0) | J33: =ROUND($G33*Settings!$B$5,0) | K33: Health | L33: 0.12 | M33: =ROUND($L33*Settings!$B$3,0) | N33: =ROUND($L33*Settings!$B$4,0) | O33: =ROUND($L33*Settings!$B$5,0) | Q33: 0 | R33: =ROUND($Q33*Settings!$B$3,0) | S33: =ROUND($Q33*Settings!$B$4,0) | T33: =ROUND($Q33*Settings!$B$5,0) | V33: 0 | W33: Happiness | X33: 0.025 | Z33: 0 | AB33: High health, slight fun loss | AC33: MVP | AD33: Eat
A34: A033 | B34: Air One Supermarket | C34: Work | D34: Work | E34: Job assigned at Corporate Soul Exchange | F34: 2 | G34: 0 | H34: =ROUND($G34*Settings!$B$3,0) | I34: =ROUND($G34*Settings!$B$4,0) | J34: =ROUND($G34*Settings!$B$5,0) | K34: From job tier | L34: 0 | M34: =ROUND($L34*Settings!$B$3,0) | N34: =ROUND($L34*Settings!$B$4,0) | O34: =ROUND($L34*Settings!$B$5,0) | P34: From job tier | Q34: 0 | R34: =ROUND($Q34*Settings!$B$3,0) | S34: =ROUND($Q34*Settings!$B$4,0) | T34: =ROUND($Q34*Settings!$B$5,0) | V34: 0 | W34: Health | X34: 0.02 | Y34: Happiness | Z34: 0.02 | AA34: One work click (2 Time Units). Money and Career come from the current job tier in Jobs_Named / Job_Progression, NOT from this row. Money is then multiplied by this building's Money Multiplier. Career is subject to the per-turn diminishing-returns rule in Settings. | AB34: v6 BUG FIX: this row used to grant Money 6%B ($6) and Career 4-6%B on top of the job tier's own pay and Career, which double-counted Career and contradicted the v5 wage table ($40-$400 per click). Both are now zero here. | AC34: MVP | AD34: Work | AH34: 1.1 | AI34: Money/Career now sourced from job tier; building Money Multiplier added
A35: A034 | B35: Regret Burger | C35: Regret Burger Classic | D35: Food | E35: None | F35: 1 | G35: 0.15 | H35: =ROUND($G35*Settings!$B$3,0) | I35: =ROUND($G35*Settings!$B$4,0) | J35: =ROUND($G35*Settings!$B$5,0) | K35: Happiness | L35: 0.04 | M35: =ROUND($L35*Settings!$B$3,0) | N35: =ROUND($L35*Settings!$B$4,0) | O35: =ROUND($L35*Settings!$B$5,0) | Q35: 0 | R35: =ROUND($Q35*Settings!$B$3,0) | S35: =ROUND($Q35*Settings!$B$4,0) | T35: =ROUND($Q35*Settings!$B$5,0) | V35: 0 | W35: Health | X35: 0.025 | Z35: 0 | AA35: Fills hunger | AB35: v5: repriced to the rebuilt money economy | AC35: MVP | AD35: Eat
A36: A035 | B36: Regret Burger | C36: Double Regret Deluxe | D36: Food | E36: None | F36: 1 | G36: 0.22 | H36: =ROUND($G36*Settings!$B$3,0) | I36: =ROUND($G36*Settings!$B$4,0) | J36: =ROUND($G36*Settings!$B$5,0) | K36: Happiness | L36: 0.07 | M36: =ROUND($L36*Settings!$B$3,0) | N36: =ROUND($L36*Settings!$B$4,0) | O36: =ROUND($L36*Settings!$B$5,0) | Q36: 0 | R36: =ROUND($Q36*Settings!$B$3,0) | S36: =ROUND($Q36*Settings!$B$4,0) | T36: =ROUND($Q36*Settings!$B$5,0) | V36: 0 | W36: Health | X36: 0.05 | Z36: 0 | AA36: Fills hunger | AB36: v5: repriced to the rebuilt money economy | AC36: MVP | AD36: Eat
A37: A036 | B37: Regret Burger | C37: Shame Shake | D37: Food | E37: None | F37: 1 | G37: 0.18 | H37: =ROUND($G37*Settings!$B$3,0) | I37: =ROUND($G37*Settings!$B$4,0) | J37: =ROUND($G37*Settings!$B$5,0) | K37: Happiness | L37: 0.05 | M37: =ROUND($L37*Settings!$B$3,0) | N37: =ROUND($L37*Settings!$B$4,0) | O37: =ROUND($L37*Settings!$B$5,0) | Q37: 0 | R37: =ROUND($Q37*Settings!$B$3,0) | S37: =ROUND($Q37*Settings!$B$4,0) | T37: =ROUND($Q37*Settings!$B$5,0) | V37: 0 | W37: Health | X37: 0.04 | Y37: Money | Z37: 0.02 | AA37: Fills hunger | AB37: v5: repriced to the rebuilt money economy | AC37: MVP | AD37: Eat
A38: A037 | B38: Regret Burger | C38: Doomscroll Fries | D38: Food | E38: None | F38: 1 | G38: 0.15 | H38: =ROUND($G38*Settings!$B$3,0) | I38: =ROUND($G38*Settings!$B$4,0) | J38: =ROUND($G38*Settings!$B$5,0) | K38: Happiness | L38: 0.04 | M38: =ROUND($L38*Settings!$B$3,0) | N38: =ROUND($L38*Settings!$B$4,0) | O38: =ROUND($L38*Settings!$B$5,0) | Q38: 0 | R38: =ROUND($Q38*Settings!$B$3,0) | S38: =ROUND($Q38*Settings!$B$4,0) | T38: =ROUND($Q38*Settings!$B$5,0) | V38: 0 | W38: Health | X38: 0.03 | Y38: Critical Thinking | Z38: 0.025 | AA38: Fills hunger | AB38: v5: repriced to the rebuilt money economy | AC38: MVP | AD38: Eat
A39: A038 | B39: Regret Burger | C39: Emotional Support Nuggets | D39: Food | E39: None | F39: 1 | G39: 0.2 | H39: =ROUND($G39*Settings!$B$3,0) | I39: =ROUND($G39*Settings!$B$4,0) | J39: =ROUND($G39*Settings!$B$5,0) | K39: Happiness | L39: 0.06 | M39: =ROUND($L39*Settings!$B$3,0) | N39: =ROUND($L39*Settings!$B$4,0) | O39: =ROUND($L39*Settings!$B$5,0) | Q39: 0 | R39: =ROUND($Q39*Settings!$B$3,0) | S39: =ROUND($Q39*Settings!$B$4,0) | T39: =ROUND($Q39*Settings!$B$5,0) | V39: 0 | W39: Health | X39: 0.04 | Z39: 0 | AA39: Fills hunger | AB39: v5: repriced to the rebuilt money economy | AC39: MVP | AD39: Eat
A40: A039 | B40: Regret Burger | C40: Coupon Meal | D40: Food | E40: None | F40: 1 | G40: 0.08 | H40: =ROUND($G40*Settings!$B$3,0) | I40: =ROUND($G40*Settings!$B$4,0) | J40: =ROUND($G40*Settings!$B$5,0) | K40: Happiness | L40: 0.025 | M40: =ROUND($L40*Settings!$B$3,0) | N40: =ROUND($L40*Settings!$B$4,0) | O40: =ROUND($L40*Settings!$B$5,0) | Q40: 0 | R40: =ROUND($Q40*Settings!$B$3,0) | S40: =ROUND($Q40*Settings!$B$4,0) | T40: =ROUND($Q40*Settings!$B$5,0) | V40: 0 | W40: Health | X40: 0.035 | Z40: 0 | AA40: Fills hunger | AB40: v5: repriced to the rebuilt money economy | AC40: MVP | AD40: Eat
...

Sheet Items_Mall
A1: Item_ID | B1: Shop / Group | C1: Item | D1: Slot | E1: Requirement | F1: Housing Requirement | G1: Cost %B | H1: Cost Short | I1: Cost Medium | J1: Cost Long | K1: Stat Bonus | L1: Bonus % | M1: Penalty Stat | N1: Penalty % | O1: Unlock / Effect | P1: Notes | Q1: MVP Priority | R1: Bonus Trigger (v5) | S1: Flat Bonus (Short) (v5)
A2: I001 | B2: Transportation | C2: Bus Pass | D2: Transport | E2: None | F2: Any | G2: 1 | H2: =ROUND($G2*Settings!$B$3,0) | I2: =ROUND($G2*Settings!$B$4,0) | J2: =ROUND($G2*Settings!$B$5,0) | L2: 0 | O2: Slightly reduced movement cost | P2: Entry mobility | Q2: MVP
A3: I002 | B3: Transportation | C3: Bicycle | D3: Transport | E3: None | F3: Any | G3: 7.5 | H3: =ROUND($G3*Settings!$B$3,0) | I3: =ROUND($G3*Settings!$B$4,0) | J3: =ROUND($G3*Settings!$B$5,0) | K3: Health | L3: 0.05 | O3: Faster movement + small Health benefit | P3: Good early investment; still reachable in the first third of the game | Q3: MVP
A4: I003 | B4: Transportation | C4: Car | D4: Transport | E4: None | F4: Any | G4: 20 | H4: =ROUND($G4*Settings!$B$3,0) | I4: =ROUND($G4*Settings!$B$4,0) | J4: =ROUND($G4*Settings!$B$5,0) | L4: 0 | O4: Fastest movement; no upkeep | P4: v4: major late-game purchase. Roughly a full game-third of savings on a mid job | Q4: MVP
A5: I004 | B5: Electronics/Appliances | C5: Computer | D5: Tech | E5: Desk recommended | F5: Any | G5: 10 | H5: =ROUND($G5*Settings!$B$3,0) | I5: =ROUND($G5*Settings!$B$4,0) | J5: =ROUND($G5*Settings!$B$5,0) | K5: Critical Thinking | L5: 0.04 | O5: Required for better jobs / work from home | P5: v4: core career item, now a real mid-game goal | Q5: MVP
A6: I005 | B6: Electronics/Appliances | C6: Mobile Phone | D6: Tech | E6: None | F6: Any | G6: 5 | H6: =ROUND($G6*Settings!$B$3,0) | I6: =ROUND($G6*Settings!$B$4,0) | J6: =ROUND($G6*Settings!$B$5,0) | K6: Career | L6: 0.03 | O6: Job calls + social events | P6: Personal item, no housing needed | Q6: MVP
A7: I006 | B7: Electronics/Appliances | C7: Camera | D7: Tech | E7: None | F7: Any | G7: 8 | H7: =ROUND($G7*Settings!$B$3,0) | I7: =ROUND($G7*Settings!$B$4,0) | J7: =ROUND($G7*Settings!$B$5,0) | K7: Connection | L7: 0.04 | O7: Creator/social route | P7: Creator/social route | Q7: MVP
A8: I007 | B8: Electronics/Appliances | C8: TV | D8: Tech | E8: Luxury apartment | F8: Luxury only | G8: 5 | H8: =ROUND($G8*Settings!$B$3,0) | I8: =ROUND($G8*Settings!$B$4,0) | J8: =ROUND($G8*Settings!$B$5,0) | K8: Happiness | L8: 0.04 | O8: Home happiness bonus | P8: v4: hard-gated. No room for a TV in low-cost housing | Q8: MVP
A9: I008 | B9: Electronics/Appliances | C9: Blu-ray | D9: Tech | E9: TV owned | F9: Luxury only | G9: 3 | H9: =ROUND($G9*Settings!$B$3,0) | I9: =ROUND($G9*Settings!$B$4,0) | J9: =ROUND($G9*Settings!$B$5,0) | K9: Happiness | L9: 0.03 | O9: Extra entertainment | P9: v4: hard-gated behind TV + luxury | Q9: MVP
A10: I009 | B10: Electronics/Appliances | C10: E-reader | D10: Tech | E10: None | F10: Any | G10: 1 | H10: =ROUND($G10*Settings!$B$3,0) | I10: =ROUND($G10*Settings!$B$4,0) | J10: =ROUND($G10*Settings!$B$5,0) | K10: Critical Thinking | L10: 0.05 | O10: Reading bonus | P10: Personal item | Q10: MVP
A11: I010 | B11: Electronics/Appliances | C11: Stereo | D11: Tech | E11: Luxury apartment | F11: Luxury only | G11: 2 | H11: =ROUND($G11*Settings!$B$3,0) | I11: =ROUND($G11*Settings!$B$4,0) | J11: =ROUND($G11*Settings!$B$5,0) | K11: Happiness | L11: 0.04 | O11: Home entertainment | P11: v4: hard-gated | Q11: MVP
A12: I011 | B12: Electronics/Appliances | C12: Watch | D12: Accessory | E12: None | F12: Any | G12: 0.25 | H12: =ROUND($G12*Settings!$B$3,0) | I12: =ROUND($G12*Settings!$B$4,0) | J12: =ROUND($G12*Settings!$B$5,0) | K12: Coolness Factor | L12: 0.05 | O12: Coolness accessory | P12: Coolness accessory | Q12: MVP
A13: I012 | B13: Electronics/Appliances | C13: Fridge | D13: Appliance | E13: Any housing | F13: Low Cost OK | G13: 9.5 | H13: =ROUND($G13*Settings!$B$3,0) | I13: =ROUND($G13*Settings!$B$4,0) | J13: =ROUND($G13*Settings!$B$5,0) | L13: 0 | O13: REQUIRED to store 2-week and 4-week groceries from Air One. Without a fridge those bulk options are unavailable and any bulk food already held spoils. Also grants a one-time Health +3 on purchase. | P13: v4: food engine, priced as a mid-game unlock | Q13: MVP | R13: ONE-TIME on purchase | S13: Health +3
A14: I013 | B14: Electronics/Appliances | C14: Stove | D14: Appliance | E14: Any housing | F14: Low Cost OK | G14: 6.5 | H14: =ROUND($G14*Settings!$B$3,0) | I14: =ROUND($G14*Settings!$B$4,0) | J14: =ROUND($G14*Settings!$B$5,0) | L14: 0 | O14: Unlocks meal prep | P14: v4: food engine | Q14: MVP | R14: Each relax action in your home | S14: Health +1
A15: I014 | B15: Electronics/Appliances | C15: Vacuum | D15: Appliance | E15: Any housing | F15: Low Cost OK | G15: 2.5 | H15: =ROUND($G15*Settings!$B$3,0) | I15: =ROUND($G15*Settings!$B$4,0) | J15: =ROUND($G15*Settings!$B$5,0) | L15: 0 | O15: Clean home health bonus | Q15: MVP | R15: ONE-TIME on purchase | S15: Health +3
A16: I015 | B16: Electronics/Appliances | C16: Cold Plunge | D16: Appliance | E16: Luxury apartment | F16: Luxury only | G16: 2 | H16: =ROUND($G16*Settings!$B$3,0) | I16: =ROUND($G16*Settings!$B$4,0) | J16: =ROUND($G16*Settings!$B$5,0) | L16: 0 | O16: Premium health item | P16: Premium health item | Q16: MVP | R16: Each exercise action in your home | S16: Health +1
A17: I016 | B17: Electronics/Appliances | C17: Hot Tub | D17: Appliance | E17: Luxury apartment | F17: Luxury only | G17: 8.5 | H17: =ROUND($G17*Settings!$B$3,0) | I17: =ROUND($G17*Settings!$B$4,0) | J17: =ROUND($G17*Settings!$B$5,0) | L17: 0 | O17: Premium happiness + hosting flavor | P17: Premium happiness + hosting | Q17: MVP | R17: Each relax action in your home | S17: Happiness +1
A18: I017 | B18: Furniture | C18: Lumpy Bed | D18: Bed | E18: Any housing | F18: Low Cost OK | G18: 0.5 | H18: =ROUND($G18*Settings!$B$3,0) | I18: =ROUND($G18*Settings!$B$4,0) | J18: =ROUND($G18*Settings!$B$5,0) | L18: 0 | O18: Small sleep bonus | P18: Cheap starter bed | Q18: MVP | R18: Each sleep action in your home | S18: Health +1
A19: I018 | B19: Furniture | C19: Nice Bed | D19: Bed | E19: Any housing | F19: Low Cost OK | G19: 5 | H19: =ROUND($G19*Settings!$B$3,0) | I19: =ROUND($G19*Settings!$B$4,0) | J19: =ROUND($G19*Settings!$B$5,0) | L19: 0 | O19: Medium sleep bonus | P19: v4: mid-game sleep upgrade | Q19: MVP | R19: Each sleep action in your home | S19: Health +2
A20: I019 | B20: Furniture | C20: Premium Bed | D20: Bed | E20: Luxury apartment | F20: Luxury only | G20: 9 | H20: =ROUND($G20*Settings!$B$3,0) | I20: =ROUND($G20*Settings!$B$4,0) | J20: =ROUND($G20*Settings!$B$5,0) | L20: 0 | O20: Large sleep bonus | P20: v4: hard-gated (was only 'recommended') | Q20: MVP | R20: Each sleep action in your home | S20: Health +3
A21: I020 | B21: Furniture | C21: Couch | D21: Furniture | E21: Luxury apartment | F21: Luxury only | G21: 6.5 | H21: =ROUND($G21*Settings!$B$3,0) | I21: =ROUND($G21*Settings!$B$4,0) | J21: =ROUND($G21*Settings!$B$5,0) | K21: Happiness | L21: 0.04 | O21: Relaxing at home bonus | P21: v4: hard-gated. No space in a bunk room | Q21: MVP
A22: I021 | B22: Furniture | C22: Bookshelf | D22: Furniture | E22: Any housing | F22: Low Cost OK | G22: 0.8 | H22: =ROUND($G22*Settings!$B$3,0) | I22: =ROUND($G22*Settings!$B$4,0) | J22: =ROUND($G22*Settings!$B$5,0) | L22: 0 | O22: Study/home critical thinking bonus | Q22: MVP | R22: Each relax action in your home | S22: Critical Thinking +1
A23: I022 | B23: Furniture | C23: Plants | D23: Furniture | E23: Any housing | F23: Low Cost OK | G23: 0.2 | H23: =ROUND($G23*Settings!$B$3,0) | I23: =ROUND($G23*Settings!$B$4,0) | J23: =ROUND($G23*Settings!$B$5,0) | L23: 0 | O23: Home wellness bonus | Q23: MVP | R23: Each relax action in your home | S23: Enlightenment +1
A24: I023 | B24: Furniture | C24: Desk | D24: Work Setup | E24: Any housing | F24: Low Cost OK | G24: 3.5 | H24: =ROUND($G24*Settings!$B$3,0) | I24: =ROUND($G24*Settings!$B$4,0) | J24: =ROUND($G24*Settings!$B$5,0) | L24: 0 | O24: Required for better work-from-home efficiency | P24: Needed for work-from-home | Q24: MVP | R24: Each work-from-home action | S24: Critical Thinking +1
A25: I024 | B25: Furniture | C25: Ergonomic Chair | D25: Work Setup | E25: Luxury apartment | F25: Luxury only | G25: 6 | H25: =ROUND($G25*Settings!$B$3,0) | I25: =ROUND($G25*Settings!$B$4,0) | J25: =ROUND($G25*Settings!$B$5,0) | L25: 0 | O25: Health + work comfort | P25: v4: hard-gated | Q25: MVP | R25: Each work-from-home action | S25: Health +1
A26: I025 | B26: Furniture | C26: Pet Bed | D26: Pet Item | E26: Own pet | F26: Low Cost OK | G26: 1.5 | H26: =ROUND($G26*Settings!$B$3,0) | I26: =ROUND($G26*Settings!$B$4,0) | J26: =ROUND($G26*Settings!$B$5,0) | L26: 0 | O26: Pet health support | Q26: MVP | R26: Each play-with-pet action in your home | S26: Pet Health +1
A27: I026 | B27: Furniture | C27: Pet Toys | D27: Pet Item | E27: Own pet | F27: Low Cost OK | G27: 0.35 | H27: =ROUND($G27*Settings!$B$3,0) | I27: =ROUND($G27*Settings!$B$4,0) | J27: =ROUND($G27*Settings!$B$5,0) | L27: 0 | O27: Pet happiness support | Q27: MVP | R27: Each play-with-pet action in your home | S27: Pet Happiness +1
A28: I027 | B28: Furniture | C28: Dining Table | D28: Furniture | E28: Luxury apartment | F28: Luxury only | G28: 4.5 | H28: =ROUND($G28*Settings!$B$3,0) | I28: =ROUND($G28*Settings!$B$4,0) | J28: =ROUND($G28*Settings!$B$5,0) | L28: 0 | O28: Hosting friends support | P28: v4: hard-gated. Hosting requires a dining room | Q28: MVP | R28: Each relax action in your home | S28: Health +1
A29: I028 | B29: Furniture | C29: Mirror | D29: Furniture | E29: Any housing | F29: Low Cost OK | G29: 0.9 | H29: =ROUND($G29*Settings!$B$3,0) | I29: =ROUND($G29*Settings!$B$4,0) | J29: =ROUND($G29*Settings!$B$5,0) | L29: 0 | O29: Flex/check outfit | Q29: MVP | R29: Each relax action in your home | S29: Coolness Factor +1
A30: I029 | B30: Clothing | C30: Casual Clothes | D30: Outfit | E30: None | F30: Any | G30: 0.5 | H30: =ROUND($G30*Settings!$B$3,0) | I30: =ROUND($G30*Settings!$B$4,0) | J30: =ROUND($G30*Settings!$B$5,0) | L30: 0 | O30: Required for low-tier jobs | P30: UNCHANGED ON PURPOSE: must stay affordable after the 30%B homeless cheque alongside 20%B low rent | Q30: MVP
A31: I030 | B31: Clothing | C31: Smart Clothes | D31: Outfit | E31: Casual clothes | F31: Any | G31: 4 | H31: =ROUND($G31*Settings!$B$3,0) | I31: =ROUND($G31*Settings!$B$4,0) | J31: =ROUND($G31*Settings!$B$5,0) | K31: Career | L31: 0.03 | O31: Required for mid-tier jobs | P31: v4: mid-tier job gate | Q31: MVP
A32: I031 | B32: Clothing | C32: Business Clothes | D32: Outfit | E32: Smart clothes | F32: Any | G32: 5 | H32: =ROUND($G32*Settings!$B$3,0) | I32: =ROUND($G32*Settings!$B$4,0) | J32: =ROUND($G32*Settings!$B$5,0) | K32: Career | L32: 0.05 | O32: Required for high/elite jobs | P32: v4: high/elite job gate, now a real investment | Q32: MVP
A33: I032 | B33: Clothing | C33: Dressy Clothes | D33: Outfit | E33: None | F33: Any | G33: 3 | H33: =ROUND($G33*Settings!$B$3,0) | I33: =ROUND($G33*Settings!$B$4,0) | J33: =ROUND($G33*Settings!$B$5,0) | K33: Coolness Factor | L33: 0.04 | O33: Required for club/VIP actions | P33: v4: club/VIP gate | Q33: MVP
